<?xml version="1.0" ?>
<!-- =================================================================================== -->
<!-- |    This document was autogenerated by xacro from openhand.xacro                 | -->
<!-- |    EDITING THIS FILE BY HAND IS NOT RECOMMENDED                                 | -->
<!-- =================================================================================== -->
<robot name="openhand" xmlns:xacro="http://www.ros.org/wiki/xacro">

  <!-- Gripper description -->

  <link name="gripper_base_link">
    <visual>
      <origin rpy="1.57079632679 0 -1.57079632679" xyz="0.06 0.017 0"/>
      <geometry>
        <mesh filename="package://yale_openhand_O/meshes/base_link.STL"/>
      </geometry>
  <material name="coolgrey" >
    <color rgba="0.5843137254901961 0.6392156862745098 0.6509803921568628 1.0" />
  </material>
    </visual>
    <inertial>
      <origin rpy="0 0 0" xyz="0.03 0 0."/>
      <mass value="0.7"/>
      <inertia ixx="0.01" ixy="0.0" ixz="0.0" iyy="0.01" iyz="0.0" izz="0.01"/>
    </inertial>
    <collision>
      <origin rpy="1.57079632679 0 -1.57079632679" xyz="0.06 0.017 0"/>
      <geometry>
        <mesh filename="package://yale_openhand_O/meshes/base_link.STL"/>
      </geometry>
    </collision>
  </link>

  <link name="finger_1_1">
    <inertial>
      <origin rpy="0 0 0" xyz="0 0 0"/>
      <mass value="0.1"/>
      <inertia ixx="0.01" ixy="0.0" ixz="0.0" iyy="0.01" iyz="0.0" izz="0.01"/>
    </inertial>
    <visual>
  <material name="coolgrey" >
    <color rgba="0.5843137254901961 0.6392156862745098 0.6509803921568628 1.0" />
  </material>
      <origin rpy="1.57079632679 3.14159265359 -1.57079632679" xyz="-0.00 0.0 0.00"/>
      <geometry>
        <!-- <cylinder length="0.002" radius="0.018" /> -->
        <mesh filename="package://yale_openhand_O/meshes/swivel_1.STL"/>
      </geometry>
    </visual>
    <collision>
      <origin rpy="0 1.57079632679 0 " xyz="0.00 0.0 0.00"/>
      <geometry>
        <cylinder length="0.002" radius="0.018"/>
      </geometry>
    </collision>
  </link>

  <link name="finger_1_2">
    <inertial>
      <origin rpy="0 0 0" xyz="0 0 0"/>
      <mass value="0.1"/>
      <inertia ixx="0.01" ixy="0.0" ixz="0.0" iyy="0.01" iyz="0.0" izz="0.01"/>
    </inertial>
    <visual>
  <material name="lightgrey" >
    <color rgba="0.8470588235294118 0.8627450980392157 0.8392156862745098 1.0" />
  </material>
      <origin rpy="0 -3.141592653592 2.4" xyz="-0.00 0.0753 0.008"/>
      <geometry>
        <mesh filename="package://yale_openhand_O/meshes/proximal_O.STL" scale="0.00100 0.00100 0.00100"/>
      </geometry>
    </visual>
    <collision>
      <origin rpy="0 -3.141592653592 2.4" xyz="-0.00 0.0753 0.008"/>
      <geometry>
        <mesh filename="package://yale_openhand_O/meshes/proximal_O.STL" scale="0.00100 0.00100 0.00100"/>
      </geometry>
    </collision>
  </link>

  <link name="finger_1_3">
      <inertial>
      <origin rpy="0 0 0" xyz="0 0 0"/>
      <mass value="0.1"/>
      <inertia ixx="0.01" ixy="0.0" ixz="0.0" iyy="0.01" iyz="0.0" izz="0.01"/>
    </inertial>
    <visual>
      <geometry>
        <mesh filename="package://allegro_hand_description/meshes/allsight_fine01.STL"/>
      </geometry>
      <material name="white">
        <color rgba=".9 .9 .9 1"/>
      </material>
    </visual>
    <collision>
      <geometry>
        <mesh filename="package://allegro_hand_description/meshes/allsight_fine01.STL"/>
      </geometry>
    </collision>
  </link>

  <link name="finger_2_1">
    <inertial>
      <origin rpy="0 0 0" xyz="0 0 0"/>
      <mass value="0.1"/>
      <inertia ixx="0.01" ixy="0.0" ixz="0.0" iyy="0.01" iyz="0.0" izz="0.01"/>
    </inertial>
    <visual>
  <material name="coolgrey" >
    <color rgba="0.5843137254901961 0.6392156862745098 0.6509803921568628 1.0" />
  </material>
      <origin rpy="1.57079632679 3.14159265359 -1.57079632679" xyz="-0.00 0.0 0.00"/>
      <geometry>
        <mesh filename="package://yale_openhand_O/meshes/swivel_1.STL"/>
      </geometry>
    </visual>
    <collision>
      <origin rpy="0 1.57079632679 0 " xyz="0.00 0.0 0.00"/>
      <geometry>
        <cylinder length="0.002" radius="0.018"/>
      </geometry>
    </collision>
  </link>

  <link name="finger_2_2">
    <inertial>
      <origin rpy="0 0 0" xyz="0 0 0"/>
      <mass value="0.1"/>
      <inertia ixx="0.01" ixy="0.0" ixz="0.0" iyy="0.01" iyz="0.0" izz="0.01"/>
    </inertial>
    <visual>
  <material name="lightgrey" >
    <color rgba="0.8470588235294118 0.8627450980392157 0.8392156862745098 1.0" />
  </material>
      <origin rpy="0 -3.141592653592 2.4" xyz="-0.00 0.0753 0.008"/>
      <geometry>
        <mesh filename="package://yale_openhand_O/meshes/proximal_O.STL" scale="0.00100 0.00100 0.00100"/>
      </geometry>
    </visual>
    <collision>
      <origin rpy="0 -3.141592653592 2.4" xyz="-0.00 0.0753 0.008"/>
      <geometry>
        <mesh filename="package://yale_openhand_O/meshes/proximal_O.STL" scale="0.00100 0.00100 0.00100"/>
      </geometry>
    </collision>
  </link>

  <link name="finger_2_3">
      <inertial>
      <origin rpy="0 0 0" xyz="0 0 0"/>
      <mass value="0.1"/>
      <inertia ixx="0.01" ixy="0.0" ixz="0.0" iyy="0.01" iyz="0.0" izz="0.01"/>
    </inertial>
    <visual>
      <geometry>
        <mesh filename="package://allegro_hand_description/meshes/allsight_fine01.STL"/>
      </geometry>
      <material name="white">
        <color rgba=".9 .9 .9 1"/>
      </material>
    </visual>
    <collision>
      <geometry>
        <mesh filename="package://allegro_hand_description/meshes/allsight_fine01.STL"/>
      </geometry>
    </collision>
  </link>

  <link name="finger_3_2">
    <inertial>
      <origin rpy="0 0 0" xyz="0 0 0"/>
      <mass value="0.1"/>
      <inertia ixx="0.01" ixy="0.0" ixz="0.0" iyy="0.01" iyz="0.0" izz="0.01"/>
    </inertial>
    <visual>
  <material name="lightgrey" >
    <color rgba="0.8470588235294118 0.8627450980392157 0.8392156862745098 1.0" />
  </material>
      <origin rpy="0 -3.141592653592 2.4" xyz="-0.00 0.0753 0.008"/>
      <geometry>
        <mesh filename="package://yale_openhand_O/meshes/proximal_O.STL" scale="0.00100 0.00100 0.00100"/>
      </geometry>
    </visual>
    <collision>
      <origin rpy="0 -3.141592653592 2.4" xyz="-0.00 0.0753 0.008"/>
      <geometry>
        <mesh filename="package://yale_openhand_O/meshes/proximal_O.STL" scale="0.00100 0.00100 0.00100"/>
      </geometry>
    </collision>
  </link>

  <link name="finger_3_3">
      <inertial>
      <origin rpy="0 0 0" xyz="0 0 0"/>
      <mass value="0.1"/>
      <inertia ixx="0.01" ixy="0.0" ixz="0.0" iyy="0.01" iyz="0.0" izz="0.01"/>
    </inertial>
    <visual>
      <geometry>
        <mesh filename="package://allegro_hand_description/meshes/allsight_fine01.STL"/>
      </geometry>
      <material name="white">
        <color rgba=".9 .9 .9 1"/>
      </material>
    </visual>
    <collision>
      <geometry>
        <mesh filename="package://allegro_hand_description/meshes/allsight_fine01.STL"/>
      </geometry>
    </collision>
  </link>

  <!-- Joints -->

  <joint name="base_to_finger_1_1" type="revolute">
    <origin rpy="3.14159265359 0 0" xyz="-0.003 -0.034 -0.027"/>
    <parent link="gripper_base_link"/>
    <child link="finger_1_1"/>
    <limit effort="1000" lower="0" upper="1.57079632679" velocity="200"/>
    <axis xyz="1 0 0"/>
    <dynamics damping="5" friction="0.0"/>
  </joint>

  <joint name="finger_1_1_to_finger_1_2" type="revolute">
    <origin rpy="0 0 0" xyz="-0.02 +0.00725 0"/>
    <parent link="finger_1_1"/>
    <child link="finger_1_2"/>
    <limit effort="1000.0" lower="-0.1" upper="3.0" velocity="10"/>
    <axis xyz="0 0 1"/>
    <dynamics damping="5" friction="0.0"/>
  </joint>

  <joint name="finger_1_2_to_finger_1_3" type="revolute">
    <origin rpy="0 0 1.57079632679" xyz="0.000800 0.062 0"/>
    <parent link="finger_1_2"/>
    <child link="finger_1_3"/>
    <limit effort="1000.0" lower="0.0" upper="1.27" velocity="10"/>
    <axis xyz="0 0 1"/>
    <dynamics damping="5" friction="0.0"/>
  </joint>

  <joint name="base_to_finger_2_1" type="revolute">
    <origin rpy="3.14159265359 0 0" xyz="-0.003 -0.034 0.027"/>
    <parent link="gripper_base_link"/>
    <child link="finger_2_1"/>
    <limit effort="1000" lower="-1.57079632679" upper="0" velocity="200"/>
    <axis xyz="1 0 0"/>
    <dynamics damping="5" friction="0.0"/>
  </joint>

  <joint name="finger_2_1_to_finger_2_2" type="revolute">
    <origin rpy="0 0 0" xyz="-0.02 +0.00725 0"/>
    <parent link="finger_2_1"/>
    <child link="finger_2_2"/>
    <limit effort="1000" lower="-0.1" upper="3.0" velocity="10"/>
    <axis xyz="0 0 1"/>
    <dynamics damping="5" friction="0.0"/>
  </joint>

  <joint name="finger_2_2_to_finger_2_3" type="revolute">
    <origin rpy="0 0 1.57079632679" xyz="0.000800 0.062 0"/>
    <parent link="finger_2_2"/>
    <child link="finger_2_3"/>
    <limit effort="1000" lower="0.0" upper="1.27" velocity="10"/>
    <axis xyz="0 0 1"/>
    <dynamics damping="5" friction="0.0"/>
  </joint>

  <joint name="base_to_finger_3_2" type="revolute">
    <origin rpy="0 0 0" xyz="-0.023 0.045 0.000000"/>
    <parent link="gripper_base_link"/>
    <child link="finger_3_2"/>
    <limit effort="1000" lower="-0.1" upper="3.0" velocity="10"/>
    <axis xyz="0 0 1"/>
    <dynamics damping="5" friction="0.0"/>
  </joint>

  <joint name="finger_3_2_to_finger_3_3" type="revolute">
    <origin rpy="0 0 1.57079632679" xyz="0.000800 0.062 0"/>
    <parent link="finger_3_2"/>
    <child link="finger_3_3"/>
    <limit effort="1000" lower="0.0" upper="1.27" velocity="10"/>
    <axis xyz="0 0 1"/>
    <dynamics damping="5" friction="0.0"/>
  </joint>



</robot>

